Workbook

Sheet Resumo
A1: RESUMO — BENCHMARK AI ASSISTANTS
A2: TCC UNISINOS — Marco Dall'Alba — Pontuações por dimensão (0–100 total)
A4: Dimensão | B4: claude_code | C4: opencode | D4: codex_cli | E4: Máx
A5: D1 — Entregáveis & Boot | B5: =claude_code!D11 -> 15 | C5: =opencode!D11 -> 10 | D5: =codex_cli!D11 -> 10 | E5: 15
A6: D2 — Integração LLM & Streaming | B6: =claude_code!D27 -> 20 | C6: =opencode!D27 -> 15 | D6: =codex_cli!D27 -> 15 | E6: 20
A7: D3 — Multi-turn & Persistência | B7: =claude_code!D41 -> 15 | C7: =opencode!D41 -> 15 | D7: =codex_cli!D41 -> 15 | E7: 15
A8: D4 — Funcionalidades | B8: =claude_code!D57 -> 20 | C8: =opencode!D57 -> 20 | D8: =codex_cli!D57 -> 20 | E8: 20
A9: D5 — Robustez | B9: =claude_code!D72 -> 10 | C9: =opencode!D72 -> 10 | D9: =codex_cli!D72 -> 10 | E9: 10
A10: D6 — Testes | B10: =claude_code!D85 -> 10 | C10: =opencode!D85 -> 7 | D10: =codex_cli!D85 -> 10 | E10: 10
A11: D7 — Qualidade de Código | B11: =claude_code!D100 -> 5 | C11: =opencode!D100 -> 5 | D11: =codex_cli!D100 -> 5 | E11: 5
A12: D8 — Documentação & Segurança | B12: =claude_code!D113 -> 5 | C12: =opencode!D113 -> 5 | D12: =codex_cli!D113 -> 5 | E12: 5
A13: TOTAL | B13: =IFERROR(SUM(B5:B12),"") -> 100 | C13: =IFERROR(SUM(C5:C12),"") -> 87 | D13: =IFERROR(SUM(D5:D12),"") -> 90 | E13: 100
A15: Notas gerais / comportamentos inesperados

Sheet claude_code
A1: SCORESHEET — CLAUDE CODE
A2: Benchmark: Avaliação Empírica de Assistentes de IA — TCC UNISINOS — Marco Dall'Alba
D3: Run:
A4: # | B4: Critério / Verificação | C4: Pts máx | D4: Pontuação | E4: Notas / Observações
A5: D1 — Entregáveis & Boot (G1, G2, G13) | D5: Máx 15
A6: Critérios de pontuação
A7: 15 | B7: App boota, UI carrega, componentes React presentes, docker compose up funciona
A8: 10 | B8: App boota e UI carrega, mas Docker falha ou componentes são arquivo único
A9: 5 | B9: App boota mas UI tem erros visíveis; ou apenas Docker funciona
A10: 0 | B10: App não boota (npm install falha, syntax error, porta não responde)
A11: → | B11: PONTUAÇÃO ATRIBUÍDA (escolha um valor dos critérios acima) | C11: (0–15) | D11: 15
A12: Checklist de verificação
A13: ☐ | B13: App boota (npm run dev / npm start) | D13: OK
A14: ☐ | B14: UI carrega em http://localhost:3000 sem erros de console | D14: OK
A15: ☐ | B15: Componentes React separados (não arquivo único) | D15: OK
A16: ☐ | B16: Tailwind CSS aplicado | D16: OK
A17: ☐ | B17: Dockerfile presente | D17: OK
A18: ☐ | B18: docker compose up --build funciona | D18: OK
A20: D2 — Integração LLM & Streaming (G3, G4) | D20: Máx 20
A21: Critérios de pontuação
A22: 20 | B22: SDK configurado 100% via env, streaming incremental confirmado visualmente, modelo configurável via OPENAI_MODEL
A23: 15 | B23: Streaming funciona mas modelo ou URL parcialmente hardcoded
A24: 10 | B24: SDK presente e configurado via env, mas streaming não é incremental (resposta completa aparece de uma vez)
A25: 5 | B25: Código de integração presente e correto sintaticamente mas nunca produz streaming real
A26: 0 | B26: Sem integração LLM; resposta estática ou endpoint inexistente
A27: → | B27: PONTUAÇÃO ATRIBUÍDA (escolha um valor dos critérios acima) | C27: (0–20) | D27: 20
A28: Checklist de verificação
A29: ☐ | B29: SDK Vercel AI (@ai-sdk/openai) presente | D29: OK
A30: ☐ | B30: OPENAI_BASE_URL lido de env (não hardcoded) | D30: OK
A31: ☐ | B31: OPENAI_MODEL lido de env (não hardcoded) | D31: OK
A32: ☐ | B32: Tokens aparecem incrementalmente na UI (streaming real) | D32: OK
A33: ☐ | B33: streamText + useChat utilizados | D33: OK
A35: D3 — Multi-turn & Persistência (G5, G6) | D35: Máx 15
A36: Critérios de pontuação
A37: 15 | B37: Histórico correto (G5 + unit test), sobrevive restart, bounded com TTL, SQLite ou Redis (não array em memória)
A38: 10 | B38: Persiste corretamente mas sem TTL ou sem caps; ou unit test de multi-turn payload ausente
A39: 5 | B39: Persiste mas apenas em memória (não sobrevive restart)
A40: 0 | B40: Sem persistência; cada mensagem é processada sem contexto
A41: → | B41: PONTUAÇÃO ATRIBUÍDA (escolha um valor dos critérios acima) | C41: (0–15) | D41: 15
A42: Checklist de verificação
...

Sheet opencode
A1: SCORESHEET — OPENCODE
A2: Benchmark: Avaliação Empírica de Assistentes de IA — TCC UNISINOS — Marco Dall'Alba
D3: Run:
A4: # | B4: Critério / Verificação | C4: Pts máx | D4: Pontuação | E4: Notas / Observações
A5: D1 — Entregáveis & Boot (G1, G2, G13) | D5: Máx 15
A6: Critérios de pontuação
A7: 15 | B7: App boota, UI carrega, componentes React presentes, docker compose up funciona
A8: 10 | B8: App boota e UI carrega, mas Docker falha ou componentes são arquivo único | E8: Falha ao executar com docker compose up
A9: 5 | B9: App boota mas UI tem erros visíveis; ou apenas Docker funciona
A10: 0 | B10: App não boota (npm install falha, syntax error, porta não responde)
A11: → | B11: PONTUAÇÃO ATRIBUÍDA (escolha um valor dos critérios acima) | C11: (0–15) | D11: 10
A12: Checklist de verificação
A13: ☐ | B13: App boota (npm run dev / npm start) | D13: OK
A14: ☐ | B14: UI carrega em http://localhost:3000 sem erros de console | D14: OK
A15: ☐ | B15: Componentes React separados (não arquivo único) | D15: OK
A16: ☐ | B16: Tailwind CSS aplicado | D16: OK
A17: ☐ | B17: Dockerfile presente | D17: OK
A18: ☐ | B18: docker compose up --build funciona | D18: NOK
A20: D2 — Integração LLM & Streaming (G3, G4) | D20: Máx 20
A21: Critérios de pontuação
A22: 20 | B22: SDK configurado 100% via env, streaming incremental confirmado visualmente, modelo configurável via OPENAI_MODEL | E22: Criou uma logica invalida para buscar a ENV OPENAI_BASE_URL priorizando um valor harded code.
A23: 15 | B23: Streaming funciona mas modelo ou URL parcialmente hardcoded
A24: 10 | B24: SDK presente e configurado via env, mas streaming não é incremental (resposta completa aparece de uma vez)
A25: 5 | B25: Código de integração presente e correto sintaticamente mas nunca produz streaming real
A26: 0 | B26: Sem integração LLM; resposta estática ou endpoint inexistente
A27: → | B27: PONTUAÇÃO ATRIBUÍDA (escolha um valor dos critérios acima) | C27: (0–20) | D27: 15
A28: Checklist de verificação
A29: ☐ | B29: SDK Vercel AI (@ai-sdk/openai) presente | D29: OK
A30: ☐ | B30: OPENAI_BASE_URL lido de env (não hardcoded) | D30: NOK
A31: ☐ | B31: OPENAI_MODEL lido de env (não hardcoded) | D31: OK
A32: ☐ | B32: Tokens aparecem incrementalmente na UI (streaming real) | D32: OK
A33: ☐ | B33: streamText + useChat utilizados | D33: OK
A35: D3 — Multi-turn & Persistência (G5, G6) | D35: Máx 15
A36: Critérios de pontuação
A37: 15 | B37: Histórico correto (G5 + unit test), sobrevive restart, bounded com TTL, SQLite ou Redis (não array em memória)
A38: 10 | B38: Persiste corretamente mas sem TTL ou sem caps; ou unit test de multi-turn payload ausente
A39: 5 | B39: Persiste mas apenas em memória (não sobrevive restart)
A40: 0 | B40: Sem persistência; cada mensagem é processada sem contexto
A41: → | B41: PONTUAÇÃO ATRIBUÍDA (escolha um valor dos critérios acima) | C41: (0–15) | D41: 15
A42: Checklist de verificação
...

Sheet codex_cli
A1: SCORESHEET — CODEX CLI
A2: Benchmark: Avaliação Empírica de Assistentes de IA — TCC UNISINOS — Marco Dall'Alba
D3: Run:
A4: # | B4: Critério / Verificação | C4: Pts máx | D4: Pontuação | E4: Notas / Observações
A5: D1 — Entregáveis & Boot (G1, G2, G13) | D5: Máx 15
A6: Critérios de pontuação
A7: 15 | B7: App boota, UI carrega, componentes React presentes, docker compose up funciona
A8: 10 | B8: App boota e UI carrega, mas Docker falha ou componentes são arquivo único | E8: Falha ao executar com docker compose up
A9: 5 | B9: App boota mas UI tem erros visíveis; ou apenas Docker funciona
A10: 0 | B10: App não boota (npm install falha, syntax error, porta não responde)
A11: → | B11: PONTUAÇÃO ATRIBUÍDA (escolha um valor dos critérios acima) | C11: (0–15) | D11: 10
A12: Checklist de verificação
A13: ☐ | B13: App boota (npm run dev / npm start) | D13: OK
A14: ☐ | B14: UI carrega em http://localhost:3000 sem erros de console | D14: OK
A15: ☐ | B15: Componentes React separados (não arquivo único) | D15: OK
A16: ☐ | B16: Tailwind CSS aplicado | D16: OK
A17: ☐ | B17: Dockerfile presente | D17: OK
A18: ☐ | B18: docker compose up --build funciona | D18: NOK
A20: D2 — Integração LLM & Streaming (G3, G4) | D20: Máx 20
A21: Critérios de pontuação
A22: 20 | B22: SDK configurado 100% via env, streaming incremental confirmado visualmente, modelo configurável via OPENAI_MODEL
A23: 15 | B23: Streaming funciona mas modelo ou URL parcialmente hardcoded | E23: Url Harded Code
A24: 10 | B24: SDK presente e configurado via env, mas streaming não é incremental (resposta completa aparece de uma vez)
A25: 5 | B25: Código de integração presente e correto sintaticamente mas nunca produz streaming real
A26: 0 | B26: Sem integração LLM; resposta estática ou endpoint inexistente
A27: → | B27: PONTUAÇÃO ATRIBUÍDA (escolha um valor dos critérios acima) | C27: (0–20) | D27: 15
A28: Checklist de verificação
A29: ☐ | B29: SDK Vercel AI (@ai-sdk/openai) presente | D29: OK
A30: ☐ | B30: OPENAI_BASE_URL lido de env (não hardcoded) | D30: NOK | E30: Url Harded Code
A31: ☐ | B31: OPENAI_MODEL lido de env (não hardcoded) | D31: OK
A32: ☐ | B32: Tokens aparecem incrementalmente na UI (streaming real) | D32: OK
A33: ☐ | B33: streamText + useChat utilizados | D33: OK
A35: D3 — Multi-turn & Persistência (G5, G6) | D35: Máx 15
A36: Critérios de pontuação
A37: 15 | B37: Histórico correto (G5 + unit test), sobrevive restart, bounded com TTL, SQLite ou Redis (não array em memória)
A38: 10 | B38: Persiste corretamente mas sem TTL ou sem caps; ou unit test de multi-turn payload ausente
A39: 5 | B39: Persiste mas apenas em memória (não sobrevive restart)
A40: 0 | B40: Sem persistência; cada mensagem é processada sem contexto
A41: → | B41: PONTUAÇÃO ATRIBUÍDA (escolha um valor dos critérios acima) | C41: (0–15) | D41: 15
A42: Checklist de verificação
...
